
x==========x]
[2024-06-04 12:45:08,566: INFO: main: *******************]
[2024-06-04 12:45:08,566: INFO: main: >>>>>> stage Evaluation stage started <<<<<<]
[2024-06-04 12:45:08,566: INFO: common: yaml file: config\config.yaml loaded successfully]
[2024-06-04 12:45:08,575: INFO: common: yaml file: params.yaml loaded successfully]
[2024-06-04 12:45:08,578: INFO: common: created directory at: artifacts]
[2024-06-04 12:45:09,184: WARNING: saving_utils: Compiled the loaded model, but the compiled metrics have yet to be built. `model.compile_metrics` will be empty until you train or evaluate the model.]
[2024-06-04 12:45:47,349: INFO: common: json file saved at: scores.json]
[2024-06-04 12:45:47,359: INFO: common: json file saved at: scores.json]
[2024-06-04 12:46:06,747: INFO: helpers: Initialized MLflow to track repo "TTNamUS/Kidney-Disease-Classification-Project"]
[2024-06-04 12:46:06,747: INFO: helpers: Repository TTNamUS/Kidney-Disease-Classification-Project initialized!]
[2024-06-04 12:51:08,882: INFO: main: *******************]
[2024-06-04 12:51:08,882: INFO: main: >>>>>> stage Evaluation stage started <<<<<<]
[2024-06-04 12:51:08,882: INFO: common: yaml file: config\config.yaml loaded successfully]
[2024-06-04 12:51:08,889: INFO: common: yaml file: params.yaml loaded successfully]
[2024-06-04 12:51:08,889: INFO: common: created directory at: artifacts]
[2024-06-04 12:51:09,460: WARNING: saving_utils: Compiled the loaded model, but the compiled metrics have yet to be built. `model.compile_metrics` will be empty until you train or evaluate the model.]
[2024-06-04 12:51:48,451: INFO: common: json file saved at: scores.json]
[2024-06-04 12:51:48,451: INFO: common: json file saved at: scores.json]
[2024-06-04 12:52:05,432: INFO: helpers: Initialized MLflow to track repo "TTNamUS/Kidney-Disease-Classification-Project"]
[2024-06-04 12:52:05,432: INFO: helpers: Repository TTNamUS/Kidney-Disease-Classification-Project initialized!]
[2024-06-04 12:52:20,134: WARNING: connectionpool: Retrying (Retry(total=4, connect=5, read=4, redirect=5, status=5)) after connection broken by 'RemoteDisconnected('Remote end closed connection without response')': /TTNamUS/Kidney-Disease-Classification-Project.mlflow/api/2.0/mlflow/runs/create]
[2024-06-04 12:55:24,981: INFO: main: >>>>>> stage Evaluation stage completed <<<<<<

x==========x]
[2024-06-04 12:55:49,718: INFO: main: *******************]
[2024-06-04 12:55:49,719: INFO: main: >>>>>> stage Evaluation stage started <<<<<<]
[2024-06-04 12:55:49,721: INFO: common: yaml file: config\config.yaml loaded successfully]
[2024-06-04 12:55:49,726: INFO: common: yaml file: params.yaml loaded successfully]
[2024-06-04 12:55:49,727: INFO: common: created directory at: artifacts]
[2024-06-04 12:55:50,133: WARNING: saving_utils: Compiled the loaded model, but the compiled metrics have yet to be built. `model.compile_metrics` will be empty until you train or evaluate the model.]
[2024-06-04 12:56:24,458: INFO: common: json file saved at: scores.json]
[2024-06-04 12:56:24,458: INFO: common: json file saved at: scores.json]
[2024-06-04 12:56:26,802: INFO: helpers: Initialized MLflow to track repo "TTNamUS/Kidney-Disease-Classification-Project"]
[2024-06-04 12:56:26,802: INFO: helpers: Repository TTNamUS/Kidney-Disease-Classification-Project initialized!]
[2024-06-04 12:57:32,022: INFO: main: >>>>>> stage Evaluation stage completed <<<<<<

x==========x]
[2024-06-04 16:01:00,811: INFO: stage_01_data_ingestion: >>>>>> stage Data Ingestion stage started <<<<<<]
[2024-06-04 16:01:00,815: INFO: common: yaml file: config\config.yaml loaded successfully]
[2024-06-04 16:01:00,817: INFO: common: yaml file: params.yaml loaded successfully]
[2024-06-04 16:01:00,817: INFO: common: created directory at: artifacts]
[2024-06-04 16:01:00,818: INFO: common: created directory at: artifacts/data_ingestion]
[2024-06-04 16:01:00,818: INFO: data_ingestion: Downloading data from https://drive.google.com/file/d/1vlhZ5c7abUKF8xXERIw6m9Te8fW7ohw3/view?usp=sharing into file artifacts/data_ingestion/data.zip]
[2024-06-04 16:01:19,725: INFO: data_ingestion: Downloaded data from https://drive.google.com/file/d/1vlhZ5c7abUKF8xXERIw6m9Te8fW7ohw3/view?usp=sharing into file artifacts/data_ingestion/data.zip]
[2024-06-04 16:01:20,980: INFO: stage_01_data_ingestion: >>>>>> stage Data Ingestion stage completed <<<<<<

x==========x]
[2024-06-04 16:02:21,144: INFO: stage_02_prepare_base_model: *******************]
[2024-06-04 16:02:21,146: INFO: stage_02_prepare_base_model: >>>>>> stage Prepare base model started <<<<<<]
[2024-06-04 16:02:21,152: INFO: common: yaml file: config\config.yaml loaded successfully]
[2024-06-04 16:02:21,158: INFO: common: yaml file: params.yaml loaded successfully]
[2024-06-04 16:02:21,158: INFO: common: created directory at: artifacts]
[2024-06-04 16:02:21,159: INFO: common: created directory at: artifacts/prepare_base_model]
[2024-06-04 16:02:22,544: WARNING: saving_api: You are saving your model as an HDF5 file via `model.save()` or `keras.saving.save_model(model)`. This file format is considered legacy. We recommend using instead the native Keras format, e.g. `model.save('my_model.keras')` or `keras.saving.save_model(model, 'my_model.keras')`. ]
[2024-06-04 16:02:25,387: WARNING: saving_api: You are saving your model as an HDF5 file via `model.save()` or `keras.saving.save_model(model)`. This file format is considered legacy. We recommend using instead the native Keras format, e.g. `model.save('my_model.keras')` or `keras.saving.save_model(model, 'my_model.keras')`. ]
[2024-06-04 16:02:25,786: INFO: stage_02_prepare_base_model: >>>>>> stage Prepare base model completed <<<<<<

x==========x]
[2024-06-04 16:02:37,723: INFO: stage_03_model_training: *******************]
[2024-06-04 16:02:37,723: INFO: stage_03_model_training: >>>>>> stage Training started <<<<<<]
[2024-06-04 16:02:37,728: INFO: common: yaml file: config\config.yaml loaded successfully]
[2024-06-04 16:02:37,731: INFO: common: yaml file: params.yaml loaded successfully]
[2024-06-04 16:02:37,732: INFO: common: created directory at: artifacts]
[2024-06-04 16:02:37,733: INFO: common: created directory at: artifacts\training]
[2024-06-04 16:02:38,342: WARNING: saving_utils: Compiled the loaded model, but the compiled metrics have yet to be built. `model.compile_metrics` will be empty until you train or evaluate the model.]
[2024-06-04 16:05:22,656: WARNING: saving_api: You are saving your model as an HDF5 file via `model.save()` or `keras.saving.save_model(model)`. This file format is considered legacy. We recommend using instead the native Keras format, e.g. `model.save('my_model.keras')` or `keras.saving.save_model(model, 'my_model.keras')`. ]
[2024-06-04 16:05:23,458: INFO: stage_03_model_training: >>>>>> stage Training completed <<<<<<

x==========x]
[2024-06-04 16:05:57,433: INFO: stage_04_model_evaluation: *******************]
[2024-06-04 16:05:57,434: INFO: stage_04_model_evaluation: >>>>>> stage Evaluation stage started <<<<<<]
[2024-06-04 16:05:57,440: INFO: common: yaml file: config\config.yaml loaded successfully]
[2024-06-04 16:05:57,443: INFO: common: yaml file: params.yaml loaded successfully]
[2024-06-04 16:05:57,443: INFO: common: created directory at: artifacts]
[2024-06-04 16:05:58,725: WARNING: saving_utils: Compiled the loaded model, but the compiled metrics have yet to be built. `model.compile_metrics` will be empty until you train or evaluate the model.]
[2024-06-04 16:06:57,652: INFO: common: json file saved at: scores.json]
[2024-06-04 16:06:57,662: INFO: common: json file saved at: scores.json]
[2024-06-04 16:07:00,583: INFO: helpers: Initialized MLflow to track repo "TTNamUS/Kidney-Disease-Classification-Project"]
[2024-06-04 16:07:00,585: INFO: helpers: Repository TTNamUS/Kidney-Disease-Classification-Project initialized!]
[2024-06-04 16:08:22,394: INFO: stage_04_model_evaluation: >>>>>> stage Evaluation stage completed <<<<<<

x==========x]
[2024-06-04 16:16:09,319: INFO: stage_04_model_evaluation: *******************]
[2024-06-04 16:16:09,323: INFO: stage_04_model_evaluation: >>>>>> stage Evaluation stage started <<<<<<]
[2024-06-04 16:16:09,340: INFO: common: yaml file: config\config.yaml loaded successfully]
[2024-06-04 16:16:09,345: INFO: common: yaml file: params.yaml loaded successfully]
[2024-06-04 16:16:09,347: INFO: common: created directory at: artifacts]
[2024-06-04 16:16:11,656: WARNING: saving_utils: Compiled the loaded model, but the compiled metrics have yet to be built. `model.compile_metrics` will be empty until you train or evaluate the model.]
[2024-06-04 16:17:01,715: INFO: common: json file saved at: scores.json]
[2024-06-04 16:17:01,722: INFO: common: json file saved at: scores.json]
[2024-06-04 16:17:01,728: INFO: stage_04_model_evaluation: >>>>>> stage Evaluation stage completed <<<<<<

x==========x]
[2024-06-04 16:25:59,844: INFO: _internal: [31m[1mWARNING: This is a development server. Do not use it in a production deployment. Use a production WSGI server instead.[0m
 * Running on all addresses (0.0.0.0)
 * Running on http://127.0.0.1:8080
 * Running on http://192.168.1.12:8080]
[2024-06-04 16:25:59,844: INFO: _internal: [33mPress CTRL+C to quit[0m]
[2024-06-04 16:26:07,723: INFO: _internal: 127.0.0.1 - - [04/Jun/2024 16:26:07] "GET / HTTP/1.1" 200 -]
[2024-06-04 16:26:27,537: ERROR: app: Exception on /predict [POST]]
Traceback (most recent call last):
  File "C:\Users\drive\miniconda3\envs\kidney\Lib\site-packages\flask\app.py", line 1473, in wsgi_app
    response = self.full_dispatch_request()
               ^^^^^^^^^^^^^^^^^^^^^^^^^^^^
  File "C:\Users\drive\miniconda3\envs\kidney\Lib\site-packages\flask\app.py", line 882, in full_dispatch_request
    rv = self.handle_user_exception(e)
         ^^^^^^^^^^^^^^^^^^^^^^^^^^^^^
  File "C:\Users\drive\miniconda3\envs\kidney\Lib\site-packages\flask_cors\extension.py", line 178, in wrapped_function
    return cors_after_request(app.make_response(f(*args, **kwargs)))
                                                ^^^^^^^^^^^^^^^^^^
  File "C:\Users\drive\miniconda3\envs\kidney\Lib\site-packages\flask\app.py", line 880, in full_dispatch_request
    rv = self.dispatch_request()
         ^^^^^^^^^^^^^^^^^^^^^^^
  File "C:\Users\drive\miniconda3\envs\kidney\Lib\site-packages\flask\app.py", line 865, in dispatch_request
    return self.ensure_sync(self.view_functions[rule.endpoint])(**view_args)  # type: ignore[no-any-return]
           ^^^^^^^^^^^^^^^^^^^^^^^^^^^^^^^^^^^^^^^^^^^^^^^^^^^^^^^^^^^^^^^^^
  File "C:\Users\drive\miniconda3\envs\kidney\Lib\site-packages\flask_cors\decorator.py", line 130, in wrapped_function
    resp = make_response(f(*args, **kwargs))
                         ^^^^^^^^^^^^^^^^^^
  File "D:\MY FOLDER\MY LEARNING\TTNamUS\LearnAI\Kidney-Disease-Classification-Project\app.py", line 44, in predictRoute
    result = clApp.classifier.predict()
             ^^^^^^^^^^^^^^^^^^^^^^^^^^
  File "d:\my folder\my learning\ttnamus\learnai\kidney-disease-classification-project\src\cnnClassifier\pipeline\prediction.py", line 16, in predict
    model = load_model(os.path.join("model", "model.h5"))
            ^^^^^^^^^^^^^^^^^^^^^^^^^^^^^^^^^^^^^^^^^^^^^
  File "C:\Users\drive\miniconda3\envs\kidney\Lib\site-packages\keras\src\saving\saving_api.py", line 183, in load_model
    return legacy_h5_format.load_model_from_hdf5(
           ^^^^^^^^^^^^^^^^^^^^^^^^^^^^^^^^^^^^^^
  File "C:\Users\drive\miniconda3\envs\kidney\Lib\site-packages\keras\src\legacy\saving\legacy_h5_format.py", line 116, in load_model_from_hdf5
    f = h5py.File(filepath, mode="r")
        ^^^^^^^^^^^^^^^^^^^^^^^^^^^^^
  File "C:\Users\drive\miniconda3\envs\kidney\Lib\site-packages\h5py\_hl\files.py", line 562, in __init__
    fid = make_fid(name, mode, userblock_size, fapl, fcpl, swmr=swmr)
          ^^^^^^^^^^^^^^^^^^^^^^^^^^^^^^^^^^^^^^^^^^^^^^^^^^^^^^^^^^^
  File "C:\Users\drive\miniconda3\envs\kidney\Lib\site-packages\h5py\_hl\files.py", line 235, in make_fid
    fid = h5f.open(name, flags, fapl=fapl)
          ^^^^^^^^^^^^^^^^^^^^^^^^^^^^^^^^
  File "h5py\\_objects.pyx", line 54, in h5py._objects.with_phil.wrapper
  File "h5py\\_objects.pyx", line 55, in h5py._objects.with_phil.wrapper
  File "h5py\\h5f.pyx", line 102, in h5py.h5f.open
FileNotFoundError: [Errno 2] Unable to synchronously open file (unable to open file: name = 'model\model.h5', errno = 2, error message = 'No such file or directory', flags = 0, o_flags = 0)
[2024-06-04 16:26:27,557: INFO: _internal: 127.0.0.1 - - [04/Jun/2024 16:26:27] "[35m[1mPOST /predict HTTP/1.1[0m" 500 -]
[2024-06-04 16:27:40,040: INFO: _internal: 127.0.0.1 - - [04/Jun/2024 16:27:40] "GET / HTTP/1.1" 200 -]
[2024-06-04 16:27:48,426: ERROR: app: Exception on /predict [POST]]
Traceback (most recent call last):
  File "C:\Users\drive\miniconda3\envs\kidney\Lib\site-packages\flask\app.py", line 1473, in wsgi_app
    response = self.full_dispatch_request()
               ^^^^^^^^^^^^^^^^^^^^^^^^^^^^
  File "C:\Users\drive\miniconda3\envs\kidney\Lib\site-packages\flask\app.py", line 882, in full_dispatch_request
    rv = self.handle_user_exception(e)
         ^^^^^^^^^^^^^^^^^^^^^^^^^^^^^
  File "C:\Users\drive\miniconda3\envs\kidney\Lib\site-packages\flask_cors\extension.py", line 178, in wrapped_function
    return cors_after_request(app.make_response(f(*args, **kwargs)))
                                                ^^^^^^^^^^^^^^^^^^
  File "C:\Users\drive\miniconda3\envs\kidney\Lib\site-packages\flask\app.py", line 880, in full_dispatch_request
    rv = self.dispatch_request()
         ^^^^^^^^^^^^^^^^^^^^^^^
  File "C:\Users\drive\miniconda3\envs\kidney\Lib\site-packages\flask\app.py", line 865, in dispatch_request
    return self.ensure_sync(self.view_functions[rule.endpoint])(**view_args)  # type: ignore[no-any-return]
           ^^^^^^^^^^^^^^^^^^^^^^^^^^^^^^^^^^^^^^^^^^^^^^^^^^^^^^^^^^^^^^^^^
  File "C:\Users\drive\miniconda3\envs\kidney\Lib\site-packages\flask_cors\decorator.py", line 130, in wrapped_function
    resp = make_response(f(*args, **kwargs))
                         ^^^^^^^^^^^^^^^^^^
  File "D:\MY FOLDER\MY LEARNING\TTNamUS\LearnAI\Kidney-Disease-Classification-Project\app.py", line 44, in predictRoute
    result = clApp.classifier.predict()
             ^^^^^^^^^^^^^^^^^^^^^^^^^^
  File "d:\my folder\my learning\ttnamus\learnai\kidney-disease-classification-project\src\cnnClassifier\pipeline\prediction.py", line 16, in predict
    model = load_model(os.path.join("model", "model.h5"))
            ^^^^^^^^^^^^^^^^^^^^^^^^^^^^^^^^^^^^^^^^^^^^^
  File "C:\Users\drive\miniconda3\envs\kidney\Lib\site-packages\keras\src\saving\saving_api.py", line 183, in load_model
    return legacy_h5_format.load_model_from_hdf5(
           ^^^^^^^^^^^^^^^^^^^^^^^^^^^^^^^^^^^^^^
  File "C:\Users\drive\miniconda3\envs\kidney\Lib\site-packages\keras\src\legacy\saving\legacy_h5_format.py", line 116, in load_model_from_hdf5
    f = h5py.File(filepath, mode="r")
        ^^^^^^^^^^^^^^^^^^^^^^^^^^^^^
  File "C:\Users\drive\miniconda3\envs\kidney\Lib\site-packages\h5py\_hl\files.py", line 562, in __init__
    fid = make_fid(name, mode, userblock_size, fapl, fcpl, swmr=swmr)
          ^^^^^^^^^^^^^^^^^^^^^^^^^^^^^^^^^^^^^^^^^^^^^^^^^^^^^^^^^^^
  File "C:\Users\drive\miniconda3\envs\kidney\Lib\site-packages\h5py\_hl\files.py", line 235, in make_fid
    fid = h5f.open(name, flags, fapl=fapl)
          ^^^^^^^^^^^^^^^^^^^^^^^^^^^^^^^^
  File "h5py\\_objects.pyx", line 54, in h5py._objects.with_phil.wrapper
  File "h5py\\_objects.pyx", line 55, in h5py._objects.with_phil.wrapper
  File "h5py\\h5f.pyx", line 102, in h5py.h5f.open
FileNotFoundError: [Errno 2] Unable to synchronously open file (unable to open file: name = 'model\model.h5', errno = 2, error message = 'No such file or directory', flags = 0, o_flags = 0)
[2024-06-04 16:27:48,436: INFO: _internal: 127.0.0.1 - - [04/Jun/2024 16:27:48] "[35m[1mPOST /predict HTTP/1.1[0m" 500 -]
[2024-06-04 16:29:15,512: INFO: _internal: 127.0.0.1 - - [04/Jun/2024 16:29:15] "GET / HTTP/1.1" 200 -]
[2024-06-04 16:32:06,192: INFO: _internal: [31m[1mWARNING: This is a development server. Do not use it in a production deployment. Use a production WSGI server instead.[0m
 * Running on all addresses (0.0.0.0)
 * Running on http://127.0.0.1:8080
 * Running on http://192.168.1.12:8080]
[2024-06-04 16:32:06,195: INFO: _internal: [33mPress CTRL+C to quit[0m]
[2024-06-04 16:32:21,714: INFO: _internal: 127.0.0.1 - - [04/Jun/2024 16:32:21] "GET / HTTP/1.1" 200 -]
[2024-06-04 16:32:42,393: ERROR: app: Exception on /predict [POST]]
Traceback (most recent call last):
  File "C:\Users\drive\miniconda3\envs\kidney\Lib\site-packages\flask\app.py", line 1473, in wsgi_app
    response = self.full_dispatch_request()
               ^^^^^^^^^^^^^^^^^^^^^^^^^^^^
  File "C:\Users\drive\miniconda3\envs\kidney\Lib\site-packages\flask\app.py", line 882, in full_dispatch_request
    rv = self.handle_user_exception(e)
         ^^^^^^^^^^^^^^^^^^^^^^^^^^^^^
  File "C:\Users\drive\miniconda3\envs\kidney\Lib\site-packages\flask_cors\extension.py", line 178, in wrapped_function
    return cors_after_request(app.make_response(f(*args, **kwargs)))
                                                ^^^^^^^^^^^^^^^^^^
  File "C:\Users\drive\miniconda3\envs\kidney\Lib\site-packages\flask\app.py", line 880, in full_dispatch_request
    rv = self.dispatch_request()
         ^^^^^^^^^^^^^^^^^^^^^^^
  File "C:\Users\drive\miniconda3\envs\kidney\Lib\site-packages\flask\app.py", line 865, in dispatch_request
    return self.ensure_sync(self.view_functions[rule.endpoint])(**view_args)  # type: ignore[no-any-return]
           ^^^^^^^^^^^^^^^^^^^^^^^^^^^^^^^^^^^^^^^^^^^^^^^^^^^^^^^^^^^^^^^^^
  File "C:\Users\drive\miniconda3\envs\kidney\Lib\site-packages\flask_cors\decorator.py", line 130, in wrapped_function
    resp = make_response(f(*args, **kwargs))
                         ^^^^^^^^^^^^^^^^^^
  File "D:\MY FOLDER\MY LEARNING\TTNamUS\LearnAI\Kidney-Disease-Classification-Project\app.py", line 44, in predictRoute
    result = clApp.classifier.predict()
             ^^^^^^^^^^^^^^^^^^^^^^^^^^
  File "d:\my folder\my learning\ttnamus\learnai\kidney-disease-classification-project\src\cnnClassifier\pipeline\prediction.py", line 16, in predict
    model = load_model(os.path.join("model", "model.h5"))
            ^^^^^^^^^^^^^^^^^^^^^^^^^^^^^^^^^^^^^^^^^^^^^
  File "C:\Users\drive\miniconda3\envs\kidney\Lib\site-packages\keras\src\saving\saving_api.py", line 183, in load_model
    return legacy_h5_format.load_model_from_hdf5(
           ^^^^^^^^^^^^^^^^^^^^^^^^^^^^^^^^^^^^^^
  File "C:\Users\drive\miniconda3\envs\kidney\Lib\site-packages\keras\src\legacy\saving\legacy_h5_format.py", line 116, in load_model_from_hdf5
    f = h5py.File(filepath, mode="r")
        ^^^^^^^^^^^^^^^^^^^^^^^^^^^^^
  File "C:\Users\drive\miniconda3\envs\kidney\Lib\site-packages\h5py\_hl\files.py", line 562, in __init__
    fid = make_fid(name, mode, userblock_size, fapl, fcpl, swmr=swmr)
          ^^^^^^^^^^^^^^^^^^^^^^^^^^^^^^^^^^^^^^^^^^^^^^^^^^^^^^^^^^^
  File "C:\Users\drive\miniconda3\envs\kidney\Lib\site-packages\h5py\_hl\files.py", line 235, in make_fid
    fid = h5f.open(name, flags, fapl=fapl)
          ^^^^^^^^^^^^^^^^^^^^^^^^^^^^^^^^
  File "h5py\\_objects.pyx", line 54, in h5py._objects.with_phil.wrapper
  File "h5py\\_objects.pyx", line 55, in h5py._objects.with_phil.wrapper
  File "h5py\\h5f.pyx", line 102, in h5py.h5f.open
FileNotFoundError: [Errno 2] Unable to synchronously open file (unable to open file: name = 'model\model.h5', errno = 2, error message = 'No such file or directory', flags = 0, o_flags = 0)
[2024-06-04 16:32:42,413: INFO: _internal: 127.0.0.1 - - [04/Jun/2024 16:32:42] "[35m[1mPOST /predict HTTP/1.1[0m" 500 -]
[2024-06-04 23:49:59,687: INFO: _internal: [31m[1mWARNING: This is a development server. Do not use it in a production deployment. Use a production WSGI server instead.[0m
 * Running on all addresses (0.0.0.0)
 * Running on http://127.0.0.1:8080
 * Running on http://192.168.1.12:8080]
[2024-06-04 23:49:59,689: INFO: _internal: [33mPress CTRL+C to quit[0m]
[2024-06-04 23:50:48,229: INFO: _internal: [31m[1mWARNING: This is a development server. Do not use it in a production deployment. Use a production WSGI server instead.[0m
 * Running on all addresses (0.0.0.0)
 * Running on http://127.0.0.1:8080
 * Running on http://192.168.1.12:8080]
[2024-06-04 23:50:48,229: INFO: _internal: [33mPress CTRL+C to quit[0m]
[2024-06-04 23:50:51,563: INFO: _internal: 127.0.0.1 - - [04/Jun/2024 23:50:51] "GET / HTTP/1.1" 200 -]
[2024-06-04 23:50:58,073: ERROR: app: Exception on /predict [POST]]
Traceback (most recent call last):
  File "C:\Users\drive\miniconda3\envs\kidney\Lib\site-packages\flask\app.py", line 1473, in wsgi_app
    response = self.full_dispatch_request()
               ^^^^^^^^^^^^^^^^^^^^^^^^^^^^
  File "C:\Users\drive\miniconda3\envs\kidney\Lib\site-packages\flask\app.py", line 882, in full_dispatch_request
    rv = self.handle_user_exception(e)
         ^^^^^^^^^^^^^^^^^^^^^^^^^^^^^
  File "C:\Users\drive\miniconda3\envs\kidney\Lib\site-packages\flask_cors\extension.py", line 178, in wrapped_function
    return cors_after_request(app.make_response(f(*args, **kwargs)))
                                                ^^^^^^^^^^^^^^^^^^
  File "C:\Users\drive\miniconda3\envs\kidney\Lib\site-packages\flask\app.py", line 880, in full_dispatch_request
    rv = self.dispatch_request()
         ^^^^^^^^^^^^^^^^^^^^^^^
  File "C:\Users\drive\miniconda3\envs\kidney\Lib\site-packages\flask\app.py", line 865, in dispatch_request
    return self.ensure_sync(self.view_functions[rule.endpoint])(**view_args)  # type: ignore[no-any-return]
           ^^^^^^^^^^^^^^^^^^^^^^^^^^^^^^^^^^^^^^^^^^^^^^^^^^^^^^^^^^^^^^^^^
  File "C:\Users\drive\miniconda3\envs\kidney\Lib\site-packages\flask_cors\decorator.py", line 130, in wrapped_function
    resp = make_response(f(*args, **kwargs))
                         ^^^^^^^^^^^^^^^^^^
  File "D:\MY FOLDER\MY LEARNING\TTNamUS\LearnAI\Kidney-Disease-Classification-Project\app.py", line 44, in predictRoute
    result = clApp.classifier.predict()
             ^^^^^^^^^^^^^^^^^^^^^^^^^^
  File "d:\my folder\my learning\ttnamus\learnai\kidney-disease-classification-project\src\cnnClassifier\pipeline\prediction.py", line 16, in predict
    model = load_model(os.path.join("model", "model.h5"))
            ^^^^^^^^^^^^^^^^^^^^^^^^^^^^^^^^^^^^^^^^^^^^^
  File "C:\Users\drive\miniconda3\envs\kidney\Lib\site-packages\keras\src\saving\saving_api.py", line 183, in load_model
    return legacy_h5_format.load_model_from_hdf5(
           ^^^^^^^^^^^^^^^^^^^^^^^^^^^^^^^^^^^^^^
  File "C:\Users\drive\miniconda3\envs\kidney\Lib\site-packages\keras\src\legacy\saving\legacy_h5_format.py", line 116, in load_model_from_hdf5
    f = h5py.File(filepath, mode="r")
        ^^^^^^^^^^^^^^^^^^^^^^^^^^^^^
  File "C:\Users\drive\miniconda3\envs\kidney\Lib\site-packages\h5py\_hl\files.py", line 562, in __init__
    fid = make_fid(name, mode, userblock_size, fapl, fcpl, swmr=swmr)
          ^^^^^^^^^^^^^^^^^^^^^^^^^^^^^^^^^^^^^^^^^^^^^^^^^^^^^^^^^^^
  File "C:\Users\drive\miniconda3\envs\kidney\Lib\site-packages\h5py\_hl\files.py", line 235, in make_fid
    fid = h5f.open(name, flags, fapl=fapl)
          ^^^^^^^^^^^^^^^^^^^^^^^^^^^^^^^^
  File "h5py\\_objects.pyx", line 54, in h5py._objects.with_phil.wrapper
  File "h5py\\_objects.pyx", line 55, in h5py._objects.with_phil.wrapper
  File "h5py\\h5f.pyx", line 102, in h5py.h5f.open
FileNotFoundError: [Errno 2] Unable to synchronously open file (unable to open file: name = 'model\model.h5', errno = 2, error message = 'No such file or directory', flags = 0, o_flags = 0)
[2024-06-04 23:50:58,103: INFO: _internal: 127.0.0.1 - - [04/Jun/2024 23:50:58] "[35m[1mPOST /predict HTTP/1.1[0m" 500 -]
[2024-06-04 23:54:11,568: INFO: _internal: [31m[1mWARNING: This is a development server. Do not use it in a production deployment. Use a production WSGI server instead.[0m
 * Running on all addresses (0.0.0.0)
 * Running on http://127.0.0.1:8080
 * Running on http://192.168.1.12:8080]
[2024-06-04 23:54:11,568: INFO: _internal: [33mPress CTRL+C to quit[0m]
[2024-06-04 23:54:13,912: INFO: _internal: 127.0.0.1 - - [04/Jun/2024 23:54:13] "GET / HTTP/1.1" 200 -]
[2024-06-04 23:54:21,823: INFO: _internal: 127.0.0.1 - - [04/Jun/2024 23:54:21] "GET / HTTP/1.1" 200 -]
[2024-06-04 23:54:27,430: ERROR: app: Exception on /predict [POST]]
Traceback (most recent call last):
  File "C:\Users\drive\miniconda3\envs\kidney\Lib\site-packages\flask\app.py", line 1473, in wsgi_app
    response = self.full_dispatch_request()
               ^^^^^^^^^^^^^^^^^^^^^^^^^^^^
  File "C:\Users\drive\miniconda3\envs\kidney\Lib\site-packages\flask\app.py", line 882, in full_dispatch_request
    rv = self.handle_user_exception(e)
         ^^^^^^^^^^^^^^^^^^^^^^^^^^^^^
  File "C:\Users\drive\miniconda3\envs\kidney\Lib\site-packages\flask_cors\extension.py", line 178, in wrapped_function
    return cors_after_request(app.make_response(f(*args, **kwargs)))
                                                ^^^^^^^^^^^^^^^^^^
  File "C:\Users\drive\miniconda3\envs\kidney\Lib\site-packages\flask\app.py", line 880, in full_dispatch_request
    rv = self.dispatch_request()
         ^^^^^^^^^^^^^^^^^^^^^^^
  File "C:\Users\drive\miniconda3\envs\kidney\Lib\site-packages\flask\app.py", line 865, in dispatch_request
    return self.ensure_sync(self.view_functions[rule.endpoint])(**view_args)  # type: ignore[no-any-return]
           ^^^^^^^^^^^^^^^^^^^^^^^^^^^^^^^^^^^^^^^^^^^^^^^^^^^^^^^^^^^^^^^^^
  File "C:\Users\drive\miniconda3\envs\kidney\Lib\site-packages\flask_cors\decorator.py", line 130, in wrapped_function
    resp = make_response(f(*args, **kwargs))
                         ^^^^^^^^^^^^^^^^^^
  File "D:\MY FOLDER\MY LEARNING\TTNamUS\LearnAI\Kidney-Disease-Classification-Project\app.py", line 44, in predictRoute
    result = clApp.classifier.predict()
             ^^^^^^^^^^^^^^^^^^^^^^^^^^
  File "d:\my folder\my learning\ttnamus\learnai\kidney-disease-classification-project\src\cnnClassifier\pipeline\prediction.py", line 16, in predict
    model = load_model(os.path.join("model", "model.h5"))
            ^^^^^^^^^^^^^^^^^^^^^^^^^^^^^^^^^^^^^^^^^^^^^
  File "C:\Users\drive\miniconda3\envs\kidney\Lib\site-packages\keras\src\saving\saving_api.py", line 183, in load_model
    return legacy_h5_format.load_model_from_hdf5(
           ^^^^^^^^^^^^^^^^^^^^^^^^^^^^^^^^^^^^^^
  File "C:\Users\drive\miniconda3\envs\kidney\Lib\site-packages\keras\src\legacy\saving\legacy_h5_format.py", line 116, in load_model_from_hdf5
    f = h5py.File(filepath, mode="r")
        ^^^^^^^^^^^^^^^^^^^^^^^^^^^^^
  File "C:\Users\drive\miniconda3\envs\kidney\Lib\site-packages\h5py\_hl\files.py", line 562, in __init__
    fid = make_fid(name, mode, userblock_size, fapl, fcpl, swmr=swmr)
          ^^^^^^^^^^^^^^^^^^^^^^^^^^^^^^^^^^^^^^^^^^^^^^^^^^^^^^^^^^^
  File "C:\Users\drive\miniconda3\envs\kidney\Lib\site-packages\h5py\_hl\files.py", line 235, in make_fid
    fid = h5f.open(name, flags, fapl=fapl)
          ^^^^^^^^^^^^^^^^^^^^^^^^^^^^^^^^
  File "h5py\\_objects.pyx", line 54, in h5py._objects.with_phil.wrapper
  File "h5py\\_objects.pyx", line 55, in h5py._objects.with_phil.wrapper
  File "h5py\\h5f.pyx", line 102, in h5py.h5f.open
FileNotFoundError: [Errno 2] Unable to synchronously open file (unable to open file: name = 'model\model.h5', errno = 2, error message = 'No such file or directory', flags = 0, o_flags = 0)
[2024-06-04 23:54:27,441: INFO: _internal: 127.0.0.1 - - [04/Jun/2024 23:54:27] "[35m[1mPOST /predict HTTP/1.1[0m" 500 -]
[2024-06-04 23:56:01,207: INFO: _internal: 127.0.0.1 - - [04/Jun/2024 23:56:01] "GET / HTTP/1.1" 200 -]
[2024-06-05 00:03:30,204: INFO: _internal: [31m[1mWARNING: This is a development server. Do not use it in a production deployment. Use a production WSGI server instead.[0m
 * Running on all addresses (0.0.0.0)
 * Running on http://127.0.0.1:8080
 * Running on http://192.168.1.12:8080]
[2024-06-05 00:03:30,205: INFO: _internal: [33mPress CTRL+C to quit[0m]
[2024-06-05 00:03:37,249: INFO: _internal: 127.0.0.1 - - [05/Jun/2024 00:03:37] "GET / HTTP/1.1" 200 -]
[2024-06-05 00:03:45,563: WARNING: saving_utils: Compiled the loaded model, but the compiled metrics have yet to be built. `model.compile_metrics` will be empty until you train or evaluate the model.]
[2024-06-05 00:03:48,486: ERROR: app: Exception on /predict [POST]]
Traceback (most recent call last):
  File "C:\Users\drive\miniconda3\envs\kidney\Lib\site-packages\flask\app.py", line 1473, in wsgi_app
    response = self.full_dispatch_request()
               ^^^^^^^^^^^^^^^^^^^^^^^^^^^^
  File "C:\Users\drive\miniconda3\envs\kidney\Lib\site-packages\flask\app.py", line 882, in full_dispatch_request
    rv = self.handle_user_exception(e)
         ^^^^^^^^^^^^^^^^^^^^^^^^^^^^^
  File "C:\Users\drive\miniconda3\envs\kidney\Lib\site-packages\flask_cors\extension.py", line 178, in wrapped_function
    return cors_after_request(app.make_response(f(*args, **kwargs)))
                                                ^^^^^^^^^^^^^^^^^^
  File "C:\Users\drive\miniconda3\envs\kidney\Lib\site-packages\flask\app.py", line 880, in full_dispatch_request
    rv = self.dispatch_request()
         ^^^^^^^^^^^^^^^^^^^^^^^
  File "C:\Users\drive\miniconda3\envs\kidney\Lib\site-packages\flask\app.py", line 865, in dispatch_request
    return self.ensure_sync(self.view_functions[rule.endpoint])(**view_args)  # type: ignore[no-any-return]
           ^^^^^^^^^^^^^^^^^^^^^^^^^^^^^^^^^^^^^^^^^^^^^^^^^^^^^^^^^^^^^^^^^
  File "C:\Users\drive\miniconda3\envs\kidney\Lib\site-packages\flask_cors\decorator.py", line 130, in wrapped_function
    resp = make_response(f(*args, **kwargs))
                         ^^^^^^^^^^^^^^^^^^
  File "D:\MY FOLDER\MY LEARNING\TTNamUS\LearnAI\Kidney-Disease-Classification-Project\app.py", line 44, in predictRoute
    result = clApp.classifier.predict()
             ^^^^^^^^^^^^^^^^^^^^^^^^^^
  File "d:\my folder\my learning\ttnamus\learnai\kidney-disease-classification-project\src\cnnClassifier\pipeline\prediction.py", line 22, in predict
    result = np.argmax(model.predict(test_image), axis=1)
                       ^^^^^^^^^^^^^^^^^^^^^^^^^
  File "C:\Users\drive\miniconda3\envs\kidney\Lib\site-packages\keras\src\utils\traceback_utils.py", line 122, in error_handler
    raise e.with_traceback(filtered_tb) from None
  File "C:\Users\drive\miniconda3\envs\kidney\Lib\encodings\cp1252.py", line 19, in encode
    return codecs.charmap_encode(input,self.errors,encoding_table)[0]
           ^^^^^^^^^^^^^^^^^^^^^^^^^^^^^^^^^^^^^^^^^^^^^^^^^^^^^^^
UnicodeEncodeError: 'charmap' codec can't encode characters in position 19-38: character maps to <undefined>
[2024-06-05 00:03:48,592: INFO: _internal: 127.0.0.1 - - [05/Jun/2024 00:03:48] "[35m[1mPOST /predict HTTP/1.1[0m" 500 -]
[2024-06-05 00:04:24,559: INFO: _internal: 127.0.0.1 - - [05/Jun/2024 00:04:24] "GET / HTTP/1.1" 200 -]
[2024-06-05 00:08:16,460: WARNING: saving_utils: Compiled the loaded model, but the compiled metrics have yet to be built. `model.compile_metrics` will be empty until you train or evaluate the model.]
[2024-06-05 00:08:19,456: ERROR: app: Exception on /predict [POST]]
Traceback (most recent call last):
  File "C:\Users\drive\miniconda3\envs\kidney\Lib\site-packages\flask\app.py", line 1473, in wsgi_app
    response = self.full_dispatch_request()
               ^^^^^^^^^^^^^^^^^^^^^^^^^^^^
  File "C:\Users\drive\miniconda3\envs\kidney\Lib\site-packages\flask\app.py", line 882, in full_dispatch_request
    rv = self.handle_user_exception(e)
         ^^^^^^^^^^^^^^^^^^^^^^^^^^^^^
  File "C:\Users\drive\miniconda3\envs\kidney\Lib\site-packages\flask_cors\extension.py", line 178, in wrapped_function
    return cors_after_request(app.make_response(f(*args, **kwargs)))
                                                ^^^^^^^^^^^^^^^^^^
  File "C:\Users\drive\miniconda3\envs\kidney\Lib\site-packages\flask\app.py", line 880, in full_dispatch_request
    rv = self.dispatch_request()
         ^^^^^^^^^^^^^^^^^^^^^^^
  File "C:\Users\drive\miniconda3\envs\kidney\Lib\site-packages\flask\app.py", line 865, in dispatch_request
    return self.ensure_sync(self.view_functions[rule.endpoint])(**view_args)  # type: ignore[no-any-return]
           ^^^^^^^^^^^^^^^^^^^^^^^^^^^^^^^^^^^^^^^^^^^^^^^^^^^^^^^^^^^^^^^^^
  File "C:\Users\drive\miniconda3\envs\kidney\Lib\site-packages\flask_cors\decorator.py", line 130, in wrapped_function
    resp = make_response(f(*args, **kwargs))
                         ^^^^^^^^^^^^^^^^^^
  File "D:\MY FOLDER\MY LEARNING\TTNamUS\LearnAI\Kidney-Disease-Classification-Project\app.py", line 44, in predictRoute
    result = clApp.classifier.predict()
             ^^^^^^^^^^^^^^^^^^^^^^^^^^
  File "d:\my folder\my learning\ttnamus\learnai\kidney-disease-classification-project\src\cnnClassifier\pipeline\prediction.py", line 22, in predict
    result = np.argmax(model.predict(test_image), axis=1)
                       ^^^^^^^^^^^^^^^^^^^^^^^^^
  File "C:\Users\drive\miniconda3\envs\kidney\Lib\site-packages\keras\src\utils\traceback_utils.py", line 122, in error_handler
    raise e.with_traceback(filtered_tb) from None
  File "C:\Users\drive\miniconda3\envs\kidney\Lib\encodings\cp1252.py", line 19, in encode
    return codecs.charmap_encode(input,self.errors,encoding_table)[0]
           ^^^^^^^^^^^^^^^^^^^^^^^^^^^^^^^^^^^^^^^^^^^^^^^^^^^^^^^
UnicodeEncodeError: 'charmap' codec can't encode characters in position 19-38: character maps to <undefined>
[2024-06-05 00:08:19,494: INFO: _internal: 127.0.0.1 - - [05/Jun/2024 00:08:19] "[35m[1mPOST /predict HTTP/1.1[0m" 500 -]
